============================= test session starts ==============================
platform linux -- Python 3.12.7, pytest-8.3.4, pluggy-1.5.0 -- /home/d/Desktop/AAT/adaptive-attention-tiling-v2/venv/bin/python
cachedir: .pytest_cache
rootdir: /home/d/Desktop/AAT/adaptive-attention-tiling-v2/tests
configfile: pytest.ini
collecting ... 2024-12-10 19:08:22,415 - tests.conftest - INFO - Test session finished with 0 passed, 0 failed
2024-12-10 19:08:22,415 - tests.conftest - INFO - Test session finished with 0 passed, 0 failed
ERROR: found no collectors for /home/d/Desktop/AAT/adaptive-attention-tiling-v2/tests/test_neural/test_attention/test_pattern_dynamics.py::TestDiffusionProperties

collected 0 items / 1 error

==================================== ERRORS ====================================
_____ ERROR collecting test_neural/test_attention/test_pattern_dynamics.py _____
venv/lib/python3.12/site-packages/_pytest/python.py:493: in importtestmodule
    mod = import_path(
venv/lib/python3.12/site-packages/_pytest/pathlib.py:587: in import_path
    importlib.import_module(module_name)
/usr/lib/python3.12/importlib/__init__.py:90: in import_module
    return _bootstrap._gcd_import(name[level:], package, level)
<frozen importlib._bootstrap>:1387: in _gcd_import
    ???
<frozen importlib._bootstrap>:1360: in _find_and_load
    ???
<frozen importlib._bootstrap>:1331: in _find_and_load_unlocked
    ???
<frozen importlib._bootstrap>:935: in _load_unlocked
    ???
venv/lib/python3.12/site-packages/_pytest/assertion/rewrite.py:175: in exec_module
    source_stat, co = _rewrite_test(fn, self.config)
venv/lib/python3.12/site-packages/_pytest/assertion/rewrite.py:355: in _rewrite_test
    tree = ast.parse(source, filename=strfn)
/usr/lib/python3.12/ast.py:52: in parse
    return compile(source, filename, mode, flags,
E     File "/home/d/Desktop/AAT/adaptive-attention-tiling-v2/tests/test_neural/test_attention/test_pattern_dynamics.py", line 1067
E       assert relative_deviation < tol * 10, \  # Relaxed tolerance for final uniformity check
E                                              ^
E   SyntaxError: unexpected character after line continuation character
=========================== short test summary info ============================
ERROR tests/test_neural/test_attention/test_pattern_dynamics.py
=============================== 1 error in 0.14s ===============================
